Workbook

Sheet Hoja2
A1: orderIdentifier | B1: orderType | C1: vendor.organizationIdentifier | D1: buyer.organizationIdentifier | E1: shipFromInstructionLocation.locationIdentifier | F1: shipToLocation.locationIdentifier | G1: orderStatus | H1: createdDate | I1: requestedShipDate | J1: requestedDeliveryDate | K1: plannedShipDate | L1: plannedDeliveryDate | M1: quantity | N1: quantityUnits | O1: totalValue | P1: orderValueCurrency | Q1: lineCount | R1: totalShippedQuantity | S1: exclude | T1: sourceLink | U1: precio_unitario | V1: precio_unitario_iva
A2: 1000567495 | B2: INBOUND | C2: F & M | D2: LightTree | E2: F & M - Columbus | F2: LT-2 | H2: 2021-06-16T00:00:00 | I2: 2021-06-23T00:00:00 | J2: 2021-06-27T00:00:00 | K2: 2021-06-23T00:00:00 | L2: 2021-06-27T00:00:00 | M2: 124 | N2: EA | O2: 6200 | P2: USD | Q2: 1 | T2: http://lighttree.com/1000567495 | U2: 50 | V2: 59.5
A3: 1000567490 | B3: INBOUND | C3: Luminar | D3: LightTree | E3: Luminar - Palm Beach Gardens | F3: LT-2 | H3: 2021-06-16T00:00:00 | I3: 2021-06-23T00:00:00 | J3: 2021-06-27T00:00:00 | K3: 2021-06-23T00:00:00 | L3: 2021-06-27T00:00:00 | M3: 124 | N3: EA | O3: 117800 | P3: USD | Q3: 1 | T3: http://lighttree.com/1000567490 | U3: 950 | V3: 1130.5
A4: 1000567484 | B4: INBOUND | C4: Flexilux | D4: LightTree | E4: Flexilux - Worcester | F4: LT-2 | H4: 2021-06-16T00:00:00 | I4: 2021-06-23T00:00:00 | J4: 2021-06-27T00:00:00 | K4: 2021-06-23T00:00:00 | L4: 2021-06-27T00:00:00 | M4: 124 | N4: EA | O4: 569408 | P4: USD | Q4: 1 | T4: http://lighttree.com/1000567484 | U4: 4592 | V4: 5464.48
A5: 1000567483 | B5: INBOUND | C5: Brewers | D5: LightTree | E5: Brewers - Phoenix | F5: LT-2 | H5: 2021-06-16T00:00:00 | I5: 2021-06-23T00:00:00 | J5: 2021-06-27T00:00:00 | K5: 2021-06-23T00:00:00 | L5: 2021-06-27T00:00:00 | M5: 124 | N5: EA | O5: 159588 | P5: USD | Q5: 1 | T5: http://lighttree.com/1000567483 | U5: 1287 | V5: 1531.53
A6: 1000567481 | B6: INBOUND | C6: McGrey | D6: LightTree | E6: McGrey - Mt Sterling | F6: LT-2 | H6: 2021-06-16T00:00:00 | I6: 2021-06-23T00:00:00 | J6: 2021-06-27T00:00:00 | K6: 2021-06-23T00:00:00 | L6: 2021-06-27T00:00:00 | M6: 320 | N6: EA | O6: 316800 | P6: USD | Q6: 1 | T6: http://lighttree.com/1000567481 | U6: 990 | V6: 1178.1
A7: 1000567478 | B7: INBOUND | C7: Total Source | D7: LightTree | E7: Total Source - Waukesha | F7: LT-2 | H7: 2021-06-16T00:00:00 | I7: 2021-06-23T00:00:00 | J7: 2021-06-27T00:00:00 | K7: 2021-06-23T00:00:00 | L7: 2021-06-27T00:00:00 | M7: 320 | N7: EA | O7: 312320 | P7: USD | Q7: 1 | T7: http://lighttree.com/1000567478 | U7: 976 | V7: 1161.44
A8: 1000567477 | B8: INBOUND | C8: Hardy | D8: LightTree | E8: Hardy - Salina | F8: LT-2 | H8: 2021-06-16T00:00:00 | I8: 2021-06-23T00:00:00 | J8: 2021-06-27T00:00:00 | K8: 2021-06-23T00:00:00 | L8: 2021-06-27T00:00:00 | M8: 320 | N8: EA | O8: 7680 | P8: USD | Q8: 1 | T8: http://lighttree.com/1000567477 | U8: 24 | V8: 28.56
A9: 1000567476 | B9: INBOUND | C9: EM | D9: LightTree | E9: EM - Hemphill | F9: LT-2 | H9: 2021-06-16T00:00:00 | I9: 2021-06-23T00:00:00 | J9: 2021-06-27T00:00:00 | K9: 2021-06-23T00:00:00 | L9: 2021-06-27T00:00:00 | M9: 320 | N9: EA | O9: 6080 | P9: USD | Q9: 1 | T9: http://lighttree.com/1000567476 | U9: 19 | V9: 22.61
A10: 1000567473 | B10: INBOUND | C10: McGrey | D10: LightTree | E10: McGrey - Mt Sterling | F10: LT-2 | H10: 2021-06-16T00:00:00 | I10: 2021-06-23T00:00:00 | J10: 2021-06-27T00:00:00 | K10: 2021-06-23T00:00:00 | L10: 2021-06-27T00:00:00 | M10: 124 | N10: EA | O10: 180048 | P10: USD | Q10: 1 | T10: http://lighttree.com/1000567473 | U10: 1452 | V10: 1727.88
A11: 1000567468 | B11: INBOUND | C11: Mueller | D11: LightTree | E11: Mueller - Pittsburgh | F11: LT-2 | H11: 2021-06-16T00:00:00 | I11: 2021-06-23T00:00:00 | J11: 2021-06-27T00:00:00 | K11: 2021-06-23T00:00:00 | L11: 2021-06-27T00:00:00 | M11: 320 | N11: EA | O11: 131840 | P11: USD | Q11: 1 | T11: http://lighttree.com/1000567468 | U11: 412 | V11: 490.28
A12: 1000567464 | B12: INBOUND | C12: Thermal | D12: LightTree | E12: Thermal - Cincinnati | F12: LT-2 | H12: 2021-06-16T00:00:00 | I12: 2021-06-23T00:00:00 | J12: 2021-06-27T00:00:00 | K12: 2021-06-23T00:00:00 | L12: 2021-06-27T00:00:00 | M12: 320 | N12: EA | O12: 17600 | P12: USD | Q12: 1 | T12: http://lighttree.com/1000567464 | U12: 55 | V12: 65.45
A13: 1000567461 | B13: INBOUND | C13: Thermal | D13: LightTree | E13: Thermal - Cincinnati | F13: LT-2 | H13: 2021-06-16T00:00:00 | I13: 2021-06-23T00:00:00 | J13: 2021-06-27T00:00:00 | K13: 2021-06-23T00:00:00 | L13: 2021-06-27T00:00:00 | M13: 320 | N13: EA | O13: 17600 | P13: USD | Q13: 1 | T13: http://lighttree.com/1000567461 | U13: 55 | V13: 65.45
... A35: 1000567213 | B35: INBOUND | C35: Interalloy | D35: LightTree | E35: Interalloy - Bozeman | F35: LT-1 | H35: 2021-07-08T00:00:00 | I35: 2021-07-15T00:00:00 | J35: 2021-07-19T00:00:00 | K35: 2021-07-15T00:00:00 | L35: 2021-07-19T00:00:00 | M35: 56 | N35: EA | O35: 168 | P35: USD | Q35: 1 | T35: http://lighttree.com/1000567213 | U35: 3 | V35: 3.57
A36: 1000567215 | B36: INBOUND | C36: Alumi-lux | D36: LightTree | E36: Alumi-lux - Nashua | F36: LT-1 | H36: 2021-07-15T00:00:00 | I36: 2021-07-22T00:00:00 | J36: 2021-07-26T00:00:00 | K36: 2021-07-26T00:00:00 | M36: 44 | N36: EA | O36: 20020 | P36: USD | Q36: 1 | T36: http://lighttree.com/1000567215 | U36: 455 | V36: 541.45
A37: 1000567217 | B37: INBOUND | C37: EM | D37: LightTree | E37: EM - Hemphill | F37: LT-1 | H37: 2021-07-15T00:00:00 | I37: 2021-07-22T00:00:00 | J37: 2021-07-26T00:00:00 | K37: 2021-07-24T00:00:00 | M37: 44 | N37: EA | O37: 836 | P37: USD | Q37: 1 | T37: http://lighttree.com/1000567217 | U37: 19 | V37: 22.61
A38: 1000567229 | B38: INBOUND | C38: Thermal | D38: LightTree | E38: Thermal - Cincinnati | F38: LT-1 | H38: 2021-06-16T00:00:00 | I38: 2021-06-23T00:00:00 | J38: 2021-06-27T00:00:00 | K38: 2021-06-23T00:00:00 | L38: 2021-06-27T00:00:00 | M38: 124 | N38: EA | O38: 6820 | P38: USD | Q38: 1 | T38: http://lighttree.com/1000567229 | U38: 55 | V38: 65.45
A39: 1000567234 | B39: INBOUND | C39: Amos | D39: LightTree | E39: Amos - Philadelphia | F39: LT-1 | H39: 2021-07-15T00:00:00 | I39: 2021-07-22T00:00:00 | J39: 2021-07-26T00:00:00 | K39: 2021-07-22T00:00:00 | M39: 44 | N39: EA | O39: 2420 | P39: USD | Q39: 1 | T39: http://lighttree.com/1000567234 | U39: 55 | V39: 65.45
A40: 1000567240 | B40: INBOUND | C40: Interalloy | D40: LightTree | E40: Interalloy - Bozeman | F40: LT-1 | H40: 2021-07-15T00:00:00 | I40: 2021-07-22T00:00:00 | J40: 2021-07-26T00:00:00 | K40: 2021-07-24T00:00:00 | M40: 44 | N40: EA | O40: 220 | P40: USD | Q40: 1 | T40: http://lighttree.com/1000567240 | U40: 5 | V40: 5.95
A41: 1000567241 | B41: INBOUND | C41: Amos | D41: LightTree | E41: Amos - Philadelphia | F41: LT-1 | H41: 2021-07-08T00:00:00 | I41: 2021-07-15T00:00:00 | J41: 2021-07-19T00:00:00 | K41: 2021-07-15T00:00:00 | L41: 2021-07-19T00:00:00 | M41: 56 | N41: EA | O41: 3080 | P41: USD | Q41: 1 | T41: http://lighttree.com/1000567241 | U41: 55 | V41: 65.45
A42: 1000567244 | B42: INBOUND | C42: EM | D42: LightTree | E42: EM - Hemphill | F42: LT-1 | H42: 2021-07-08T00:00:00 | I42: 2021-07-15T00:00:00 | J42: 2021-07-19T00:00:00 | K42: 2021-07-15T00:00:00 | L42: 2021-07-19T00:00:00 | M42: 56 | N42: EA | O42: 1064 | P42: USD | Q42: 1 | T42: http://lighttree.com/1000567244 | U42: 19 | V42: 22.61
A43: 1000567248 | B43: INBOUND | C43: SA | D43: LightTree | E43: SA - Loretto | F43: LT-1 | H43: 2021-06-16T00:00:00 | I43: 2021-06-23T00:00:00 | J43: 2021-06-27T00:00:00 | K43: 2021-06-23T00:00:00 | L43: 2021-06-27T00:00:00 | M43: 512 | N43: EA | O43: 179200 | P43: USD | Q43: 1 | T43: http://lighttree.com/1000567248 | U43: 350 | V43: 416.5
A44: 1000567251 | B44: INBOUND | C44: SilverOptics | D44: LightTree | E44: SilverOptics - Dover | F44: LT-1 | H44: 2021-07-15T00:00:00 | I44: 2021-07-22T00:00:00 | J44: 2021-07-26T00:00:00 | M44: 44 | N44: EA | O44: 4752 | P44: USD | Q44: 1 | T44: http://lighttree.com/1000567251 | U44: 108 | V44: 128.52
A45: 1000567254 | B45: INBOUND | C45: Brewers | D45: LightTree | E45: Brewers - Phoenix | F45: LT-1 | H45: 2021-06-16T00:00:00 | I45: 2021-06-23T00:00:00 | J45: 2021-06-27T00:00:00 | K45: 2021-06-23T00:00:00 | L45: 2021-06-27T00:00:00 | M45: 512 | N45: EA | O45: 745472 | P45: USD | Q45: 1 | T45: http://lighttree.com/1000567254 | U45: 1456 | V45: 1732.64
A46: 1000567255 | B46: INBOUND | C46: Ripley | D46: LightTree | E46: Ripley - Trenton | F46: LT-1 | H46: 2021-07-08T00:00:00 | I46: 2021-07-15T00:00:00 | J46: 2021-07-19T00:00:00 | K46: 2021-07-15T00:00:00 | L46: 2021-07-19T00:00:00 | M46: 56 | N46: EA | O46: 17920 | P46: USD | Q46: 1 | T46: http://lighttree.com/1000567255 | U46: 320 | V46: 380.8
A47: 1000567262 | B47: INBOUND | C47: Interalloy | D47: LightTree | E47: Interalloy - Bozeman | F47: LT-1 | H47: 2021-06-16T00:00:00 | I47: 2021-06-23T00:00:00 | J47: 2021-06-27T00:00:00 | K47: 2021-06-23T00:00:00 | L47: 2021-06-27T00:00:00 | M47: 512 | N47: EA | O47: 2560 | P47: USD | Q47: 1 | T47: http://lighttree.com/1000567262 | U47: 5 | V47: 5.95
A48: 1000567264 | B48: INBOUND | C48: Ripley | D48: LightTree | E48: Ripley - Trenton | F48: LT-1 | H48: 2021-07-15T00:00:00 | I48: 2021-07-22T00:00:00 | J48: 2021-07-26T00:00:00 | M48: 44 | N48: EA | O48: 15400 | P48: USD | Q48: 1 | T48: http://lighttree.com/1000567264 | U48: 350 | V48: 416.5
A49: 1000567268 | B49: INBOUND | C49: EM | D49: LightTree | E49: EM - Hemphill | F49: LT-1 | H49: 2021-06-16T00:00:00 | I49: 2021-06-23T00:00:00 | J49: 2021-06-27T00:00:00 | K49: 2021-06-23T00:00:00 | L49: 2021-06-27T00:00:00 | M49: 512 | N49: EA | O49: 9728 | P49: USD | Q49: 1 | T49: http://lighttree.com/1000567268 | U49: 19 | V49: 22.61
A50: 1000567286 | B50: INBOUND | C50: Brewers | D50: LightTree | E50: Brewers - Phoenix | F50: LT-1 | H50: 2021-07-15T00:00:00 | I50: 2021-07-22T00:00:00 | J50: 2021-07-26T00:00:00 | K50: 2021-07-22T00:00:00 | M50: 44 | N50: EA | O50: 56628 | P50: USD | Q50: 1 | T50: http://lighttree.com/1000567286 | U50: 1287 | V50: 1531.53
A51: 1000567287 | B51: INBOUND | C51: Mueller | D51: LightTree | E51: Mueller - Pittsburgh | F51: LT-1 | H51: 2021-06-16T00:00:00 | I51: 2021-06-23T00:00:00 | J51: 2021-06-27T00:00:00 | K51: 2021-06-23T00:00:00 | L51: 2021-06-27T00:00:00 | M51: 512 | N51: EA | O51: 210944 | P51: USD | Q51: 1 | T51: http://lighttree.com/1000567287 | U51: 412 | V51: 490.28
A52: 1000567294 | B52: INBOUND | C52: Alumi-lux | D52: LightTree | E52: Alumi-lux - Nashua | F52: LT-1 | H52: 2021-06-29T00:00:00 | I52: 2021-07-06T00:00:00 | J52: 2021-07-10T00:00:00 | K52: 2021-07-10T00:00:00 | L52: 2021-07-14T00:00:00 | M52: 75 | N52: EA | O52: 34125 | P52: USD | Q52: 1 | T52: http://lighttree.com/1000567294 | U52: 455 | V52: 541.45
A53: 1000567306 | B53: INBOUND | C53: Interalloy | D53: LightTree | E53: Interalloy - Bozeman | F53: LT-1 | H53: 2021-06-16T00:00:00 | I53: 2021-06-23T00:00:00 | J53: 2021-06-27T00:00:00 | K53: 2021-06-23T00:00:00 | L53: 2021-06-27T00:00:00 | M53: 512 | N53: EA | O53: 1536 | P53: USD | Q53: 1 | T53: http://lighttree.com/1000567306 | U53: 3 | V53: 3.57
A54: 1000567310 | B54: INBOUND | C54: F & M | D54: LightTree | E54: F & M - Columbus | F54: LT-1 | H54: 2021-07-08T00:00:00 | I54: 2021-07-15T00:00:00 | J54: 2021-07-19T00:00:00 | K54: 2021-07-15T00:00:00 | L54: 2021-07-19T00:00:00 | M54: 56 | N54: EA | O54: 2800 | P54: USD | Q54: 1 | T54: http://lighttree.com/1000567310 | U54: 50 | V54: 59.5
A55: 1000567311 | B55: INBOUND | C55: Hardy | D55: LightTree | E55: Hardy - Salina | F55: LT-1 | H55: 2021-06-29T00:00:00 | I55: 2021-07-06T00:00:00 | J55: 2021-07-10T00:00:00 | K55: 2021-07-06T00:00:00 | L55: 2021-07-10T00:00:00 | M55: 75 | N55: EA | O55: 1800 | P55: USD | Q55: 1 | T55: http://lighttree.com/1000567311 | U55: 24 | V55: 28.56
A56: 1000567313 | B56: INBOUND | C56: F & M | D56: LightTree | E56: F & M - Columbus | F56: LT-1 | H56: 2021-06-16T00:00:00 | I56: 2021-06-23T00:00:00 | J56: 2021-06-27T00:00:00 | K56: 2021-06-23T00:00:00 | L56: 2021-06-27T00:00:00 | M56: 512 | N56: EA | O56: 25600 | P56: USD | Q56: 1 | T56: http://lighttree.com/1000567313 | U56: 50 | V56: 59.5
A57: 1000567318 | B57: INBOUND | C57: Interalloy | D57: LightTree | E57: Interalloy - Bozeman | F57: LT-1 | H57: 2021-07-08T00:00:00 | I57: 2021-07-15T00:00:00 | J57: 2021-07-19T00:00:00 | K57: 2021-07-15T00:00:00 | L57: 2021-07-19T00:00:00 | M57: 56 | N57: EA | O57: 280 | P57: USD | Q57: 1 | T57: http://lighttree.com/1000567318 | U57: 5 | V57: 5.95
A58: 1000567320 | B58: INBOUND | C58: Brewers | D58: LightTree | E58: Brewers - Phoenix | F58: LT-1 | H58: 2021-07-08T00:00:00 | I58: 2021-07-15T00:00:00 | J58: 2021-07-19T00:00:00 | K58: 2021-07-15T00:00:00 | L58: 2021-07-19T00:00:00 | M58: 56 | N58: EA | O58: 81536 | P58: USD | Q58: 1 | T58: http://lighttree.com/1000567320 | U58: 1456 | V58: 1732.64
A59: 1000567323 | B59: INBOUND | C59: R&J | D59: LightTree | E59: R&J - Vancouver | F59: LT-1 | H59: 2021-06-29T00:00:00 | I59: 2021-07-06T00:00:00 | J59: 2021-07-10T00:00:00 | K59: 2021-07-06T00:00:00 | L59: 2021-07-10T00:00:00 | M59: 75 | N59: EA | O59: 58050 | P59: USD | Q59: 1 | T59: http://lighttree.com/1000567323 | U59: 774 | V59: 921.06
A60: 1000567324 | B60: INBOUND | C60: McGrey | D60: LightTree | E60: McGrey - Mt Sterling | F60: LT-1 | H60: 2021-06-29T00:00:00 | I60: 2021-07-06T00:00:00 | J60: 2021-07-10T00:00:00 | K60: 2021-07-06T00:00:00 | L60: 2021-07-10T00:00:00 | M60: 75 | N60: EA | O60: 96750 | P60: USD | Q60: 1 | T60: http://lighttree.com/1000567324 | U60: 1290 | V60: 1535.1
A61: 1000567325 | B61: INBOUND | C61: Ripley | D61: LightTree | E61: Ripley - Trenton | F61: LT-1 | H61: 2021-06-16T00:00:00 | I61: 2021-06-23T00:00:00 | J61: 2021-06-27T00:00:00 | K61: 2021-06-23T00:00:00 | L61: 2021-06-27T00:00:00 | M61: 512 | N61: EA | O61: 163840 | P61: USD | Q61: 1 | T61: http://lighttree.com/1000567325 | U61: 320 | V61: 380.8
...

Sheet Hoja1
A3: Etiquetas de fila | B3: Promedio de quantity | C3: Suma de totalValue
A4: INBOUND | B4: 283.41071 | C4: 17834508
A5: LightTree | B5: 283.41071 | C5: 17834508
A6: OUTBOUND | B6: 258.69565 | C6: 8476705
A7: AHTD | B7: 272.44444 | C7: 1570661
A8: CALTRAN | B8: 296.81818 | C8: 1555833
A9: COLA | B9: 111 | C9: 122802
A10: FAA | B10: 317.5 | C10: 1012637
A11: KYTC | B11: 133 | C11: 498750
A12: MAHD | B12: 99 | C12: 247500
A13: NYDOT | B13: 262.6 | C13: 1641250
A14: QPWD | B14: 349.71429 | C14: 1827272
A15: Total general | B15: 278.09813 | C15: 26311213

Sheet Ordenes
A1: orderIdentifier | B1: orderType | C1: vendor.organizationIdentifier | D1: buyer.organizationIdentifier | E1: PublicName | F1: shipFromInstructionLocation.locationIdentifier | G1: shipToLocation.locationIdentifier | H1: orderStatus | I1: createdDate | J1: requestedShipDate | K1: requestedDeliveryDate | L1: plannedShipDate | M1: plannedDeliveryDate | N1: quantity | O1: quantityUnits | P1: totalValue | Q1: orderValueCurrency | R1: lineCount | S1: totalShippedQuantity | T1: exclude | U1: sourceLink | V1: precio_unitario | W1: precio_unitario_iva
A2: 100044349 | B2: OUTBOUND | C2: LightTree | D2: AHTD | E2: =VLOOKUP(D2,Catalogo!$A$1:$B$10,2) -> Apex Highway Technologies Division | F2: LT-1 | G2: AHTD - Bentonville | I2: 2021-06-08T00:00:00 | J2: 2021-07-20T00:00:00 | K2: 2021-07-30T00:00:00 | L2: 2021-07-23T00:00:00 | M2: 2021-07-30T00:00:00 | N2: 189 | O2: EA | P2: 236250 | Q2: USD | R2: 3 | U2: http://lighttree.com/100044349 | V2: 1250 | W2: 1487.5
A3: 100044350 | B3: OUTBOUND | C3: LightTree | D3: AHTD | E3: =VLOOKUP(D3,Catalogo!$A$1:$B$10,2) -> Apex Highway Technologies Division | F3: LT-1 | G3: AHTD - Bentonville | I3: 2021-06-08T00:00:00 | J3: 2021-07-23T00:00:00 | K3: 2021-07-30T00:00:00 | L3: 2021-07-23T00:00:00 | M3: 2021-07-30T00:00:00 | N3: 20 | O3: EA | P3: 25000 | Q3: USD | R3: 3 | U3: http://lighttree.com/100044350 | V3: 1250 | W3: 1487.5
A4: 100044353 | B4: OUTBOUND | C4: LightTree | D4: AHTD | E4: =VLOOKUP(D4,Catalogo!$A$1:$B$10,2) -> Apex Highway Technologies Division | F4: LT-1 | G4: AHTD - Bentonville | I4: 2021-06-08T00:00:00 | J4: 2021-07-13T00:00:00 | K4: 2021-07-30T00:00:00 | L4: 2021-07-23T00:00:00 | M4: 2021-07-30T00:00:00 | N4: 212 | O4: EA | P4: 265000 | Q4: USD | R4: 3 | U4: http://lighttree.com/100044353 | V4: 1250 | W4: 1487.5
A5: 100055001 | B5: OUTBOUND | C5: LightTree | D5: AHTD | E5: =VLOOKUP(D5,Catalogo!$A$1:$B$10,2) -> Apex Highway Technologies Division | F5: LT-2 | G5: AHTD - Bentonville | I5: 2017-07-11T00:00:00 | J5: 2021-08-10T00:00:00 | K5: 2021-08-18T00:00:00 | L5: 2021-08-10T00:00:00 | M5: 2021-08-18T00:00:00 | N5: 761 | O5: EA | P5: 59473 | Q5: USD | R5: 3 | U5: http://lighttree.com/100055001 | V5: 78.151117 | W5: 92.999829
A6: 100055003 | B6: OUTBOUND | C6: LightTree | D6: AHTD | E6: =VLOOKUP(D6,Catalogo!$A$1:$B$10,2) -> Apex Highway Technologies Division | F6: LT-2 | G6: AHTD - Bentonville | I6: 2017-07-20T00:00:00 | J6: 2021-08-11T00:00:00 | K6: 2021-08-14T00:00:00 | L6: 2021-08-11T00:00:00 | M6: 2021-08-14T00:00:00 | N6: 520 | O6: EA | P6: 47438 | Q6: USD | R6: 3 | U6: http://lighttree.com/100055003 | V6: 91.226923 | W6: 108.56004
A7: 100044351 | B7: OUTBOUND | C7: LightTree | D7: AHTD | E7: =VLOOKUP(D7,Catalogo!$A$1:$B$10,2) -> Apex Highway Technologies Division | F7: LT-1 | G7: AHTD - Bentonville | I7: 2021-06-08T00:00:00 | J7: 2021-07-08T00:00:00 | K7: 2021-07-15T00:00:00 | L7: 2021-07-08T00:00:00 | M7: 2021-07-15T00:00:00 | N7: 68 | O7: EA | P7: 85000 | Q7: USD | R7: 3 | U7: http://lighttree.com/100044351 | V7: 1250 | W7: 1487.5
A8: 100044352 | B8: OUTBOUND | C8: LightTree | D8: AHTD | E8: =VLOOKUP(D8,Catalogo!$A$1:$B$10,2) -> Apex Highway Technologies Division | F8: LT-1 | G8: AHTD - Bentonville | I8: 2021-06-08T00:00:00 | J8: 2021-07-08T00:00:00 | K8: 2021-07-15T00:00:00 | L8: 2021-07-08T00:00:00 | M8: 2021-07-17T00:00:00 | N8: 74 | O8: EA | P8: 92500 | Q8: USD | R8: 3 | U8: http://lighttree.com/100044352 | V8: 1250 | W8: 1487.5
A9: 100044354 | B9: OUTBOUND | C9: LightTree | D9: AHTD | E9: =VLOOKUP(D9,Catalogo!$A$1:$B$10,2) -> Apex Highway Technologies Division | F9: LT-1 | G9: AHTD - Bentonville | I9: 2021-06-08T00:00:00 | J9: 2021-06-30T00:00:00 | K9: 2021-07-07T00:00:00 | L9: 2021-06-30T00:00:00 | M9: 2021-07-07T00:00:00 | N9: 208 | O9: EA | P9: 260000 | Q9: USD | R9: 3 | U9: http://lighttree.com/100044354 | V9: 1250 | W9: 1487.5
A10: 100044355 | B10: OUTBOUND | C10: LightTree | D10: AHTD | E10: =VLOOKUP(D10,Catalogo!$A$1:$B$10,2) -> Apex Highway Technologies Division | F10: LT-1 | G10: AHTD - Bentonville | I10: 2021-06-08T00:00:00 | J10: 2021-06-30T00:00:00 | K10: 2021-07-07T00:00:00 | L10: 2021-06-30T00:00:00 | M10: 2021-07-07T00:00:00 | N10: 400 | O10: EA | P10: 500000 | Q10: USD | R10: 3 | U10: http://lighttree.com/100044355 | V10: 1250 | W10: 1487.5
A11: 100044343 | B11: OUTBOUND | C11: LightTree | D11: CALTRAN | E11: =VLOOKUP(D11,Catalogo!$A$1:$B$10,2) -> CalTranscend Systems | F11: LT-1 | G11: CALTRAN - San Diego | I11: 2021-06-11T00:00:00 | J11: 2021-07-26T00:00:00 | K11: 2021-08-03T00:00:00 | L11: 2021-07-26T00:00:00 | M11: 2021-08-03T00:00:00 | N11: 22 | O11: EA | P11: 27500 | Q11: USD | R11: 3 | U11: http://lighttree.com/100044343 | V11: 1250 | W11: 1487.5
A12: 100044344 | B12: OUTBOUND | C12: LightTree | D12: CALTRAN | E12: =VLOOKUP(D12,Catalogo!$A$1:$B$10,2) -> CalTranscend Systems | F12: LT-1 | G12: CALTRAN - San Diego | I12: 2021-06-11T00:00:00 | J12: 2021-07-28T00:00:00 | K12: 2021-08-03T00:00:00 | L12: 2021-07-26T00:00:00 | M12: 2021-08-03T00:00:00 | N12: 302 | O12: EA | P12: 377500 | Q12: USD | R12: 3 | U12: http://lighttree.com/100044344 | V12: 1250 | W12: 1487.5
A13: 100055000 | B13: OUTBOUND | C13: LightTree | D13: CALTRAN | E13: =VLOOKUP(D13,Catalogo!$A$1:$B$10,2) -> CalTranscend Systems | F13: LT-2 | G13: CALTRAN - San Diego | I13: 2017-07-20T00:00:00 | J13: 2021-08-11T00:00:00 | K13: 2021-08-14T00:00:00 | L13: 2021-08-11T00:00:00 | M13: 2021-08-14T00:00:00 | N13: 228 | O13: EA | P13: 20084 | Q13: USD | R13: 3 | U13: http://lighttree.com/100055000 | V13: 88.087719 | W13: 104.82439
... A29: 100055010 | B29: OUTBOUND | C29: LightTree | D29: FAA | E29: =VLOOKUP(D29,Catalogo!$A$1:$B$10,2) -> Flight Axis Authority | F29: LT-2 | G29: FAA - Washington | I29: 2017-07-20T00:00:00 | J29: 2021-08-11T00:00:00 | K29: 2021-08-14T00:00:00 | L29: 2021-08-11T00:00:00 | M29: 2021-08-14T00:00:00 | N29: 488 | O29: EA | P29: 35137 | Q29: USD | R29: 4 | U29: http://lighttree.com/100055010 | V29: 72.002049 | W29: 85.682439
A30: 100044322 | B30: OUTBOUND | C30: LightTree | D30: FAA | E30: =VLOOKUP(D30,Catalogo!$A$1:$B$10,2) -> Flight Axis Authority | F30: LT-2 | G30: FAA - Washington | I30: 2021-07-20T00:00:00 | J30: 2021-08-11T00:00:00 | K30: 2021-08-14T00:00:00 | N30: 400 | O30: EA | P30: 500000 | Q30: USD | R30: 3 | U30: http://lighttree.com/100044322 | V30: 1250 | W30: 1487.5
A31: 100044335 | B31: OUTBOUND | C31: LightTree | D31: KYTC | E31: =VLOOKUP(D31,Catalogo!$A$1:$B$10,2) -> Kinetic Transit Core | F31: LT-2 | G31: KYTC - Lexington | I31: 2021-06-28T00:00:00 | J31: 2021-07-20T00:00:00 | K31: 2021-07-24T00:00:00 | L31: 2021-07-20T00:00:00 | M31: 2021-07-28T00:00:00 | N31: 320 | O31: EA | P31: 400000 | Q31: USD | R31: 3 | U31: http://lighttree.com/100044335 | V31: 1250 | W31: 1487.5
A32: 100044336 | B32: OUTBOUND | C32: LightTree | D32: KYTC | E32: =VLOOKUP(D32,Catalogo!$A$1:$B$10,2) -> Kinetic Transit Core | F32: LT-2 | G32: KYTC - Lexington | I32: 2021-06-28T00:00:00 | J32: 2021-07-28T00:00:00 | K32: 2021-08-01T00:00:00 | L32: 2021-07-28T00:00:00 | M32: 2021-08-01T00:00:00 | N32: 75 | O32: EA | P32: 93750 | Q32: USD | R32: 3 | U32: http://lighttree.com/100044336 | V32: 1250 | W32: 1487.5
A33: 100044337 | B33: OUTBOUND | C33: LightTree | D33: KYTC | E33: =VLOOKUP(D33,Catalogo!$A$1:$B$10,2) -> Kinetic Transit Core | F33: LT-2 | G33: KYTC - Lexington | I33: 2021-06-28T00:00:00 | J33: 2021-07-28T00:00:00 | K33: 2021-08-01T00:00:00 | L33: 2021-07-28T00:00:00 | M33: 2021-08-01T00:00:00 | N33: 4 | O33: EA | P33: 5000 | Q33: USD | R33: 3 | U33: http://lighttree.com/100044337 | V33: 1250 | W33: 1487.5
A34: 1000567212 | B34: INBOUND | C34: Flexilux | D34: LightTree | E34: =VLOOKUP(D34,Catalogo!$A$1:$B$10,2) -> LightTree Innovations | F34: Flexilux - Worcester | G34: LT-1 | I34: 2021-07-08T00:00:00 | J34: 2021-07-15T00:00:00 | K34: 2021-07-19T00:00:00 | L34: 2021-07-15T00:00:00 | M34: 2021-07-19T00:00:00 | N34: 56 | O34: EA | P34: 134288 | Q34: USD | R34: 1 | U34: http://lighttree.com/1000567212 | V34: 2398 | W34: 2853.62
A35: 1000567213 | B35: INBOUND | C35: Interalloy | D35: LightTree | E35: =VLOOKUP(D35,Catalogo!$A$1:$B$10,2) -> LightTree Innovations | F35: Interalloy - Bozeman | G35: LT-1 | I35: 2021-07-08T00:00:00 | J35: 2021-07-15T00:00:00 | K35: 2021-07-19T00:00:00 | L35: 2021-07-15T00:00:00 | M35: 2021-07-19T00:00:00 | N35: 56 | O35: EA | P35: 168 | Q35: USD | R35: 1 | U35: http://lighttree.com/1000567213 | V35: 3 | W35: 3.57
A36: 1000567215 | B36: INBOUND | C36: Alumi-lux | D36: LightTree | E36: =VLOOKUP(D36,Catalogo!$A$1:$B$10,2) -> LightTree Innovations | F36: Alumi-lux - Nashua | G36: LT-1 | I36: 2021-07-15T00:00:00 | J36: 2021-07-22T00:00:00 | K36: 2021-07-26T00:00:00 | L36: 2021-07-26T00:00:00 | N36: 44 | O36: EA | P36: 20020 | Q36: USD | R36: 1 | U36: http://lighttree.com/1000567215 | V36: 455 | W36: 541.45
A37: 1000567217 | B37: INBOUND | C37: EM | D37: LightTree | E37: =VLOOKUP(D37,Catalogo!$A$1:$B$10,2) -> LightTree Innovations | F37: EM - Hemphill | G37: LT-1 | I37: 2021-07-15T00:00:00 | J37: 2021-07-22T00:00:00 | K37: 2021-07-26T00:00:00 | L37: 2021-07-24T00:00:00 | N37: 44 | O37: EA | P37: 836 | Q37: USD | R37: 1 | U37: http://lighttree.com/1000567217 | V37: 19 | W37: 22.61
A38: 1000567229 | B38: INBOUND | C38: Thermal | D38: LightTree | E38: =VLOOKUP(D38,Catalogo!$A$1:$B$10,2) -> LightTree Innovations | F38: Thermal - Cincinnati | G38: LT-1 | I38: 2021-06-16T00:00:00 | J38: 2021-06-23T00:00:00 | K38: 2021-06-27T00:00:00 | L38: 2021-06-23T00:00:00 | M38: 2021-06-27T00:00:00 | N38: 124 | O38: EA | P38: 6820 | Q38: USD | R38: 1 | U38: http://lighttree.com/1000567229 | V38: 55 | W38: 65.45
A39: 1000567234 | B39: INBOUND | C39: Amos | D39: LightTree | E39: =VLOOKUP(D39,Catalogo!$A$1:$B$10,2) -> LightTree Innovations | F39: Amos - Philadelphia | G39: LT-1 | I39: 2021-07-15T00:00:00 | J39: 2021-07-22T00:00:00 | K39: 2021-07-26T00:00:00 | L39: 2021-07-22T00:00:00 | N39: 44 | O39: EA | P39: 2420 | Q39: USD | R39: 1 | U39: http://lighttree.com/1000567234 | V39: 55 | W39: 65.45
A40: 1000567240 | B40: INBOUND | C40: Interalloy | D40: LightTree | E40: =VLOOKUP(D40,Catalogo!$A$1:$B$10,2) -> LightTree Innovations | F40: Interalloy - Bozeman | G40: LT-1 | I40: 2021-07-15T00:00:00 | J40: 2021-07-22T00:00:00 | K40: 2021-07-26T00:00:00 | L40: 2021-07-24T00:00:00 | N40: 44 | O40: EA | P40: 220 | Q40: USD | R40: 1 | U40: http://lighttree.com/1000567240 | V40: 5 | W40: 5.95
A41: 1000567241 | B41: INBOUND | C41: Amos | D41: LightTree | E41: =VLOOKUP(D41,Catalogo!$A$1:$B$10,2) -> LightTree Innovations | F41: Amos - Philadelphia | G41: LT-1 | I41: 2021-07-08T00:00:00 | J41: 2021-07-15T00:00:00 | K41: 2021-07-19T00:00:00 | L41: 2021-07-15T00:00:00 | M41: 2021-07-19T00:00:00 | N41: 56 | O41: EA | P41: 3080 | Q41: USD | R41: 1 | U41: http://lighttree.com/1000567241 | V41: 55 | W41: 65.45
A42: 1000567244 | B42: INBOUND | C42: EM | D42: LightTree | E42: =VLOOKUP(D42,Catalogo!$A$1:$B$10,2) -> LightTree Innovations | F42: EM - Hemphill | G42: LT-1 | I42: 2021-07-08T00:00:00 | J42: 2021-07-15T00:00:00 | K42: 2021-07-19T00:00:00 | L42: 2021-07-15T00:00:00 | M42: 2021-07-19T00:00:00 | N42: 56 | O42: EA | P42: 1064 | Q42: USD | R42: 1 | U42: http://lighttree.com/1000567244 | V42: 19 | W42: 22.61
A43: 1000567248 | B43: INBOUND | C43: SA | D43: LightTree | E43: =VLOOKUP(D43,Catalogo!$A$1:$B$10,2) -> LightTree Innovations | F43: SA - Loretto | G43: LT-1 | I43: 2021-06-16T00:00:00 | J43: 2021-06-23T00:00:00 | K43: 2021-06-27T00:00:00 | L43: 2021-06-23T00:00:00 | M43: 2021-06-27T00:00:00 | N43: 512 | O43: EA | P43: 179200 | Q43: USD | R43: 1 | U43: http://lighttree.com/1000567248 | V43: 350 | W43: 416.5
A44: 1000567251 | B44: INBOUND | C44: SilverOptics | D44: LightTree | E44: =VLOOKUP(D44,Catalogo!$A$1:$B$10,2) -> LightTree Innovations | F44: SilverOptics - Dover | G44: LT-1 | I44: 2021-07-15T00:00:00 | J44: 2021-07-22T00:00:00 | K44: 2021-07-26T00:00:00 | N44: 44 | O44: EA | P44: 4752 | Q44: USD | R44: 1 | U44: http://lighttree.com/1000567251 | V44: 108 | W44: 128.52
A45: 1000567254 | B45: INBOUND | C45: Brewers | D45: LightTree | E45: =VLOOKUP(D45,Catalogo!$A$1:$B$10,2) -> LightTree Innovations | F45: Brewers - Phoenix | G45: LT-1 | I45: 2021-06-16T00:00:00 | J45: 2021-06-23T00:00:00 | K45: 2021-06-27T00:00:00 | L45: 2021-06-23T00:00:00 | M45: 2021-06-27T00:00:00 | N45: 512 | O45: EA | P45: 745472 | Q45: USD | R45: 1 | U45: http://lighttree.com/1000567254 | V45: 1456 | W45: 1732.64
A46: 1000567255 | B46: INBOUND | C46: Ripley | D46: LightTree | E46: =VLOOKUP(D46,Catalogo!$A$1:$B$10,2) -> LightTree Innovations | F46: Ripley - Trenton | G46: LT-1 | I46: 2021-07-08T00:00:00 | J46: 2021-07-15T00:00:00 | K46: 2021-07-19T00:00:00 | L46: 2021-07-15T00:00:00 | M46: 2021-07-19T00:00:00 | N46: 56 | O46: EA | P46: 17920 | Q46: USD | R46: 1 | U46: http://lighttree.com/1000567255 | V46: 320 | W46: 380.8
A47: 1000567262 | B47: INBOUND | C47: Interalloy | D47: LightTree | E47: =VLOOKUP(D47,Catalogo!$A$1:$B$10,2) -> LightTree Innovations | F47: Interalloy - Bozeman | G47: LT-1 | I47: 2021-06-16T00:00:00 | J47: 2021-06-23T00:00:00 | K47: 2021-06-27T00:00:00 | L47: 2021-06-23T00:00:00 | M47: 2021-06-27T00:00:00 | N47: 512 | O47: EA | P47: 2560 | Q47: USD | R47: 1 | U47: http://lighttree.com/1000567262 | V47: 5 | W47: 5.95
A48: 1000567264 | B48: INBOUND | C48: Ripley | D48: LightTree | E48: =VLOOKUP(D48,Catalogo!$A$1:$B$10,2) -> LightTree Innovations | F48: Ripley - Trenton | G48: LT-1 | I48: 2021-07-15T00:00:00 | J48: 2021-07-22T00:00:00 | K48: 2021-07-26T00:00:00 | N48: 44 | O48: EA | P48: 15400 | Q48: USD | R48: 1 | U48: http://lighttree.com/1000567264 | V48: 350 | W48: 416.5
A49: 1000567268 | B49: INBOUND | C49: EM | D49: LightTree | E49: =VLOOKUP(D49,Catalogo!$A$1:$B$10,2) -> LightTree Innovations | F49: EM - Hemphill | G49: LT-1 | I49: 2021-06-16T00:00:00 | J49: 2021-06-23T00:00:00 | K49: 2021-06-27T00:00:00 | L49: 2021-06-23T00:00:00 | M49: 2021-06-27T00:00:00 | N49: 512 | O49: EA | P49: 9728 | Q49: USD | R49: 1 | U49: http://lighttree.com/1000567268 | V49: 19 | W49: 22.61
A50: 1000567286 | B50: INBOUND | C50: Brewers | D50: LightTree | E50: =VLOOKUP(D50,Catalogo!$A$1:$B$10,2) -> LightTree Innovations | F50: Brewers - Phoenix | G50: LT-1 | I50: 2021-07-15T00:00:00 | J50: 2021-07-22T00:00:00 | K50: 2021-07-26T00:00:00 | L50: 2021-07-22T00:00:00 | N50: 44 | O50: EA | P50: 56628 | Q50: USD | R50: 1 | U50: http://lighttree.com/1000567286 | V50: 1287 | W50: 1531.53
A51: 1000567287 | B51: INBOUND | C51: Mueller | D51: LightTree | E51: =VLOOKUP(D51,Catalogo!$A$1:$B$10,2) -> LightTree Innovations | F51: Mueller - Pittsburgh | G51: LT-1 | I51: 2021-06-16T00:00:00 | J51: 2021-06-23T00:00:00 | K51: 2021-06-27T00:00:00 | L51: 2021-06-23T00:00:00 | M51: 2021-06-27T00:00:00 | N51: 512 | O51: EA | P51: 210944 | Q51: USD | R51: 1 | U51: http://lighttree.com/1000567287 | V51: 412 | W51: 490.28
A52: 1000567294 | B52: INBOUND | C52: Alumi-lux | D52: LightTree | E52: =VLOOKUP(D52,Catalogo!$A$1:$B$10,2) -> LightTree Innovations | F52: Alumi-lux - Nashua | G52: LT-1 | I52: 2021-06-29T00:00:00 | J52: 2021-07-06T00:00:00 | K52: 2021-07-10T00:00:00 | L52: 2021-07-10T00:00:00 | M52: 2021-07-14T00:00:00 | N52: 75 | O52: EA | P52: 34125 | Q52: USD | R52: 1 | U52: http://lighttree.com/1000567294 | V52: 455 | W52: 541.45
A53: 1000567306 | B53: INBOUND | C53: Interalloy | D53: LightTree | E53: =VLOOKUP(D53,Catalogo!$A$1:$B$10,2) -> LightTree Innovations | F53: Interalloy - Bozeman | G53: LT-1 | I53: 2021-06-16T00:00:00 | J53: 2021-06-23T00:00:00 | K53: 2021-06-27T00:00:00 | L53: 2021-06-23T00:00:00 | M53: 2021-06-27T00:00:00 | N53: 512 | O53: EA | P53: 1536 | Q53: USD | R53: 1 | U53: http://lighttree.com/1000567306 | V53: 3 | W53: 3.57
A54: 1000567310 | B54: INBOUND | C54: F & M | D54: LightTree | E54: =VLOOKUP(D54,Catalogo!$A$1:$B$10,2) -> LightTree Innovations | F54: F & M - Columbus | G54: LT-1 | I54: 2021-07-08T00:00:00 | J54: 2021-07-15T00:00:00 | K54: 2021-07-19T00:00:00 | L54: 2021-07-15T00:00:00 | M54: 2021-07-19T00:00:00 | N54: 56 | O54: EA | P54: 2800 | Q54: USD | R54: 1 | U54: http://lighttree.com/1000567310 | V54: 50 | W54: 59.5
A55: 1000567311 | B55: INBOUND | C55: Hardy | D55: LightTree | E55: =VLOOKUP(D55,Catalogo!$A$1:$B$10,2) -> LightTree Innovations | F55: Hardy - Salina | G55: LT-1 | I55: 2021-06-29T00:00:00 | J55: 2021-07-06T00:00:00 | K55: 2021-07-10T00:00:00 | L55: 2021-07-06T00:00:00 | M55: 2021-07-10T00:00:00 | N55: 75 | O55: EA | P55: 1800 | Q55: USD | R55: 1 | U55: http://lighttree.com/1000567311 | V55: 24 | W55: 28.56
...

Sheet Catalogo
A1: buyer.organizationIdentifier | B1: publicName | C1: creationDate
A2: AHTD | B2: Apex Highway Technologies Division | C2: =TODAY() -> 46118
A3: CALTRAN | B3: CalTranscend Systems | C3: =C2-451 -> 45667
A4: COLA | B4: Core Logistics Alliance | C4: =C3-53 -> 45614
A5: FAA | B5: Flight Axis Authority | C5: =C4+96 -> 45710
A6: KYTC | B6: Kinetic Transit Core | C6: =C5-451 -> 45259
A7: LightTree | B7: LightTree Innovations | C7: =C6-53 -> 45206
A8: MAHD | B8: Meridian Advanced Highway Division | C8: =C7+96 -> 45302
A9: NYDOT | B9: New York Digital Operations Transit | C9: =C8-451 -> 44851
A10: CAT | B10: Gatos asociados SA | C10: =C9-95 -> 44756
A11: AHTD | B11: Apex Highway Technologies Division | C11: =C10-95 -> 44661
